<?xml version="1.0" ?>
<robot name="Intelligent_shelf" xmlns:xacro="http://ros.org/wiki/xacro">
  <xacro:include filename="$(find intelligent_shelf)/urdf/common_properties.xacro"/>

  <link name="world_link">
  </link>

  <joint name="shelf_base_joint" type="fixed">
    <parent link="world_link"/>
    <child link="shelf_base_link"/>
    <origin xyz="0 0 0" rpy="0 0 0" />
  </joint>

  <link name="shelf_base_link">
    <inertial>
      <origin xyz="0 0 0"/>
      <mass value="70000.0"/>
      <inertia ixx="8.090e+09" ixy="6.459e+07" ixz="2.889e+07"
               iyy="1.159e+10" iyz="1.808e+08"
               izz="1.728e+10" />
    </inertial>
    <visual>
      <origin xyz="0.50 0 0" rpy="1.57 -0 0 "/>
      <geometry>
        <mesh filename="package://intelligent_shelf/gazebo_models/base_shelf/meshes/intelligent_shelf.stl" scale="0.001 0.001 0.001"/>
      </geometry>
    <material name="light_black"/>
    </visual>
    <collision>
      <origin xyz="0 0 0 " rpy="0 0 0"/>
      <geometry>
        <mesh filename="package://intelligent_shelf/gazebo_models/base_shelf/meshes/intelligent_shelf.stl" scale="0.001 0.001 0.001"/>
      </geometry>
    </collision>
  </link>

  <joint name="shelf_bottom_joint" type="prismatic">
    <parent link="shelf_base_link"/>
    <child link="shelf_bottom_link"/>
    <origin xyz="0.01 0.42 0.63" rpy="0 0 -1.57"/>
    <limit lower="-2.0" upper="2.0" effort="100" velocity="50.0" /> 
  </joint>

  <transmission name="shelf_bottom_trans">
    <type>transmission_interface/SimpleTransmission</type>
    <actuator name="$shelf_bottom_motor">
      <!-- <hardwareInterface>hardware_interface/EffortJointInterface</hardwareInterface> -->
      <hardwareInterface>hardware_interface/PositionJointInterface</hardwareInterface>
      <mechanicalReduction>1</mechanicalReduction>
    </actuator>
    <joint name="shelf_bottom_joint">
      <!-- <hardwareInterface>hardware_interface/EffortJointInterface</hardwareInterface> -->
      <hardwareInterface>hardware_interface/PositionJointInterface</hardwareInterface>
    </joint>
  </transmission>


  <link name="shelf_bottom_link">
    <collision>
      <origin xyz="0 0 0" rpy="0 0 0"/>
      <geometry>
        <mesh filename="package://intelligent_shelf/gazebo_models/board_3/meshes/shelf_board_3.stl" scale="0.001 0.001 0.001"/>
      </geometry>
    </collision>
    <inertial>
      <origin xyz="0 0 0" />
      <mass value="2136.966" />
      <inertia ixx="2.841e+07" ixy="17.82" ixz="2.904e+05"
               iyy="1.721e+08" iyz="7.966"
               izz="1.437e+08" />
    </inertial>
    <visual>
      <origin xyz="0 -0.45 0" rpy="1.57 0 1.57"/>
      <geometry>
        <mesh filename="package://intelligent_shelf/gazebo_models/board_3/meshes/shelf_board_3.stl" scale="0.001 0.001 0.001"/>
      </geometry>
      <material name="blue"/>
    </visual>
  </link>

  <joint name="shelf_middle_joint" type="prismatic">
    <parent link="shelf_base_link"/>
    <child link="shelf_middle_link"/>
    <origin xyz="0.01 0.42 0.92" rpy="0 0 -1.57"/>
    <limit lower="-2.0" upper="2.0" effort="100" velocity="50.0" /> 
  </joint>

  <transmission name="shelf_middle_trans">
    <type>transmission_interface/SimpleTransmission</type>
    <actuator name="$shelf_middle_motor">
      <mechanicalReduction>1</mechanicalReduction>
      <!-- <hardwareInterface>hardware_interface/EffortJointInterface</hardwareInterface> -->
      <hardwareInterface>hardware_interface/PositionJointInterface</hardwareInterface>
    </actuator>
    <joint name="shelf_middle_joint">
      <!-- <hardwareInterface>hardware_interface/EffortJointInterface</hardwareInterface> -->
      <hardwareInterface>hardware_interface/PositionJointInterface</hardwareInterface>
    </joint>
  </transmission>

  <link name="shelf_middle_link">
    <collision>
      <origin xyz="0 0 0" rpy="0 0 0"/>
      <geometry>
        <mesh filename="package://intelligent_shelf/gazebo_models/board_2/meshes/shelf_board_2.stl" scale="0.001 0.001 0.001"/>
      </geometry>
    </collision>
    <inertial>
      <origin xyz="0 0 0" />
      <mass value="2136.966" />
      <inertia ixx="2.841e+07" ixy="17.82" ixz="2.904e+05"
               iyy="1.721e+08" iyz="7.966"
               izz="1.437e+08" />
      </inertial>
    <visual>
      <origin xyz="0 -0.45 0" rpy="1.57 0 1.57"/>
      <geometry>
        <mesh filename="package://intelligent_shelf/gazebo_models/board_2/meshes/shelf_board_2.stl" scale="0.001 0.001 0.001"/>
      </geometry>
      <material name="blue"/>
    </visual>
  </link>

  <joint name="shelf_top_joint" type="prismatic">
    <parent link="shelf_base_link"/>
    <child link="shelf_top_link"/>
    <origin xyz="0.01 0.42 1.21" rpy="0 0 -1.57"/>
    <limit lower="-2.0" upper="2.0" effort="100" velocity="50.0" /> 
  </joint>

  <transmission name="shelf_top_trans">
    <type>transmission_interface/SimpleTransmission</type>
    <actuator name="$shelf_top_motor">
      <!-- <hardwareInterface>hardware_interface/EffortJointInterface</hardwareInterface> -->
      <hardwareInterface>hardware_interface/PositionJointInterface</hardwareInterface>
      <mechanicalReduction>1</mechanicalReduction>
    </actuator>
    <joint name="shelf_top_joint">
      <!-- <hardwareInterface>hardware_interface/EffortJointInterface</hardwareInterface> -->
      <hardwareInterface>hardware_interface/PositionJointInterface</hardwareInterface>
    </joint>
  </transmission>

  <link name="shelf_top_link">
    <collision>
      <origin xyz="0 0 0 " rpy="0 0 0"/>
      <geometry>
        <mesh filename="package://intelligent_shelf/gazebo_models/board_1/meshes/shelf_board_1.stl" scale="0.001 0.001 0.001"/>
      </geometry>
    </collision>
    <inertial>
      <origin xyz="0 0 0 " />
      <mass value="2136.966" />
      <inertia ixx="2.841e+07" ixy="17.82" ixz="2.904e+05"
               iyy="1.721e+08" iyz="7.966"
               izz="1.437e+08" />
    </inertial>
    <visual>
      <origin xyz="0 -0.45 0" rpy="1.57 0 1.57"/>
      <geometry>
        <mesh filename="package://intelligent_shelf/gazebo_models/board_1/meshes/shelf_board_1.stl" scale="0.001 0.001 0.001"/>
      </geometry>
      <material name="blue"/>
    </visual>
  </link>

  <gazebo reference="shelf_base_link">
    <material>Gazebo/Grey</material>
  </gazebo>

  <gazebo reference="shelf_top_link">
    <material>Gazebo/Skyblue</material>
  </gazebo>

  <gazebo reference="shelf_middle_link">
    <material>Gazebo/Skyblue</material>
  </gazebo>

  <gazebo reference="shelf_bottom_link">
    <material>Gazebo/Skyblue</material>
  </gazebo>

  <gazebo>
    <plugin name="gazebo_ros_control" filename="libgazebo_ros_control.so">
      <robotNamespace>/</robotNamespace>
    </plugin>
  </gazebo>
</robot>
